Workbook

Sheet Plan de Desarrollo
C2: Control de Desarrollo
C3: Ordenado por importancia · 420 elementos · v2.0 · 2026-10-08
C4: Cambia la columna Estado (Pendiente / En progreso / Completo). La casilla ✔ se actualiza sola.
A5: Orden | B5: ✔ | C5: Estado | D5: ID | E5: Módulo | F5: Tipo | G5: Elemento | H5: Nivel | I5: Fase | J5: Sprint | K5: Grupo | L5: Historias (doc. maestro) | M5: Responsable | N5: Notas
A6: 1 | B6: =IF(C6="Completo","☑",IF(C6="En progreso","◐","☐")) | C6: Completo | D6: PLT-M06 | E6: 00 · Plataforma y Shared Kernel | F6: Mantenimiento | G6: Localización es/en con claves por módulo | H6: Imprescindible | I6: Fundación | J6: 0 | K6: Base | L6: §12 | M6: Backend | N6: Solo es (defecto) y en; recursos Platform y Accounts
A7: 2 | B7: =IF(C7="Completo","☑",IF(C7="En progreso","◐","☐")) | C7: Completo | D7: PLT-F01 | E7: 00 · Plataforma y Shared Kernel | F7: Funcionalidad | G7: Eliminar ejemplo BookStore (código, seeds, tests, tablas) | H7: Imprescindible | I7: Fundación | J7: 0 | K7: Base | L7: — | M7: Backend | N7: Código, permisos, tests y tablas eliminados (migración)
A8: 3 | B8: =IF(C8="Completo","☑",IF(C8="En progreso","◐","☐")) | C8: Completo | D8: PLT-F02 | E8: 00 · Plataforma y Shared Kernel | F8: Funcionalidad | G8: Desactivar multi-tenancy y quitar “código de empresa” del login | H8: Imprescindible | I8: Fundación | J8: 0 | K8: Base | L8: ADR-02 | M8: Backend | N8: Desactivado en API. La UI debe quitar el campo (ver prompt UI)
A9: 4 | B9: =IF(C9="Completo","☑",IF(C9="En progreso","◐","☐")) | C9: En progreso | D9: PLT-F03 | E9: 00 · Plataforma y Shared Kernel | F9: Funcionalidad | G9: Secretos fuera del repo + rotar credencial de PostgreSQL | H9: Imprescindible | I9: Fundación | J9: 0 | K9: Base | L9: OB-47-007 | M9: Backend | N9: Fuera del repo y de las imágenes. PENDIENTE: rotar la contraseña en Railway (sigue en el historial de git)
A10: 5 | B10: =IF(C10="Completo","☑",IF(C10="En progreso","◐","☐")) | C10: Completo | D10: PLT-F04 | E10: 00 · Plataforma y Shared Kernel | F10: Funcionalidad | G10: Plantilla de módulo + pruebas automáticas de arquitectura | H10: Imprescindible | I10: Fundación | J10: 0 | K10: Base | L10: TECH-02-001 | M10: Backend | N10: modules/<modulo> con 5 capas + 32 pruebas de arquitectura
A11: 6 | B11: =IF(C11="Completo","☑",IF(C11="En progreso","◐","☐")) | C11: Completo | D11: PLT-F05 | E11: 00 · Plataforma y Shared Kernel | F11: Funcionalidad | G11: Fechas en UTC (timestamptz); quitar modo legacy de Npgsql | H11: Imprescindible | I11: Fundación | J11: 0 | K11: Base | L11: ADR-06 | M11: Backend | N11: AbpClock UTC; 72 columnas migradas a timestamptz
A12: 7 | B12: =IF(C12="Completo","☑",IF(C12="En progreso","◐","☐")) | C12: Completo | D12: PLT-F06 | E12: 00 · Plataforma y Shared Kernel | F12: Funcionalidad | G12: Security headers, CORS estricto, PII desactivada en logs | H12: Imprescindible | I12: Fundación | J12: 0 | K12: Base | L12: OB-47-001 | M12: Backend | N12: HSTS, headers ABP, CORS por config, DisablePII=true
A13: 8 | B13: =IF(C13="Completo","☑",IF(C13="En progreso","◐","☐")) | C13: Completo | D13: DEV-M01 | E13: DEV · Operación, Calidad y Entrega | F13: Mantenimiento | G13: Entorno Development | H13: Imprescindible | I13: Fundación | J13: 0 | K13: Áreas transversales | L13: ENV-01-001 | M13: Backend | N13: PostgreSQL local en Docker + appsettings.secrets.json ignorado
A14: 9 | B14: =IF(C14="Completo","☑",IF(C14="En progreso","◐","☐")) | C14: Completo | D14: DEV-F01 | E14: DEV · Operación, Calidad y Entrega | F14: Funcionalidad | G14: Dockerfiles multi-stage con $PORT | H14: Imprescindible | I14: Fundación | J14: 0 | K14: Áreas transversales | L14: RELEASE-01-001 | M14: Backend | N14: Dockerfile raíz: API + Worker + Migrador en una imagen
A15: 10 | B15: =IF(C15="Completo","☑",IF(C15="En progreso","◐","☐")) | C15: En progreso | D15: DEV-F02 | E15: DEV · Operación, Calidad y Entrega | F15: Funcionalidad | G15: Servicios Railway (api, worker, migrator, web, postgres, redis) | H15: Imprescindible | I15: Fundación | J15: 0 | K15: Áreas transversales | L15: ENV-01 | M15: Backend | N15: railway/api.railway.json y worker.railway.json listos; falta crear los servicios en Railway
A16: 11 | B16: =IF(C16="Completo","☑",IF(C16="En progreso","◐","☐")) | C16: En progreso | D16: DEV-F03 | E16: DEV · Operación, Calidad y Entrega | F16: Funcionalidad | G16: Certificados OpenIddict de producción | H16: Imprescindible | I16: Fundación | J16: 0 | K16: Áreas transversales | L16: RELEASE-01-001 | M16: Backend | N16: Soporta AuthServer__CertificateBase64; falta generar el certificado de producción
A17: 12 | B17: =IF(C17="Completo","☑",IF(C17="En progreso","◐","☐")) | C17: En progreso | D17: DEV-F04 | E17: DEV · Operación, Calidad y Entrega | F17: Funcionalidad | G17: CI en cada PR (build, tests, scans) | H17: Imprescindible | I17: Fundación | J17: 0 | K17: Áreas transversales | L17: DEVOPS-01-001 | M17: Backend | N17: .github/workflows/ci.yml listo; falta primera ejecución en GitHub
... A33: 28 | B33: =IF(C33="Completo","☑",IF(C33="En progreso","◐","☐")) | C33: Completo | D33: ADM-F01 | E33: 26 · Administración y Auditoría | F33: Funcionalidad | G33: Auditoría de eventos críticos de negocio | H33: Imprescindible | I33: Fundación | J33: 1 | K33: Gobierno | L33: OB-49-001 | M33: Backend | N33: BusinessAuditEvent inmutable en Platform
A34: 29 | B34: =IF(C34="Completo","☑",IF(C34="En progreso","◐","☐")) | C34: Pendiente | D34: DEV-M02 | E34: DEV · Operación, Calidad y Entrega | F34: Mantenimiento | G34: Entorno QA/Testing | H34: Imprescindible | I34: Fundación | J34: 1 | K34: Áreas transversales | L34: ENV-01-002
A35: 30 | B35: =IF(C35="Completo","☑",IF(C35="En progreso","◐","☐")) | C35: Pendiente | D35: DEV-M03 | E35: DEV · Operación, Calidad y Entrega | F35: Mantenimiento | G35: Entorno Staging | H35: Imprescindible | I35: Fundación | J35: 1 | K35: Áreas transversales | L35: ENV-01-003
A36: 31 | B36: =IF(C36="Completo","☑",IF(C36="En progreso","◐","☐")) | C36: Pendiente | D36: DEV-F06 | E36: DEV · Operación, Calidad y Entrega | F36: Funcionalidad | G36: Promoción de imagen entre entornos + rollback | H36: Imprescindible | I36: Fundación | J36: 1 | K36: Áreas transversales | L36: DEVOPS-01-002
A37: 32 | B37: =IF(C37="Completo","☑",IF(C37="En progreso","◐","☐")) | C37: Pendiente | D37: DEV-F07 | E37: DEV · Operación, Calidad y Entrega | F37: Funcionalidad | G37: Backups automáticos + PITR | H37: Imprescindible | I37: Fundación | J37: 1 | K37: Áreas transversales | L37: OPS-01-001
A38: 33 | B38: =IF(C38="Completo","☑",IF(C38="En progreso","◐","☐")) | C38: En progreso | D38: DEV-F08 | E38: DEV · Operación, Calidad y Entrega | F38: Funcionalidad | G38: Tests de integración con PostgreSQL real | H38: Imprescindible | I38: Fundación | J38: 1 | K38: Áreas transversales | L38: QA-01-002 | M38: Backend | N38: E2E manual 33/33 contra PostgreSQL; las pruebas automáticas usan SQLite
A39: 34 | B39: =IF(C39="Completo","☑",IF(C39="En progreso","◐","☐")) | C39: En progreso | D39: DEV-F09 | E39: DEV · Operación, Calidad y Entrega | F39: Funcionalidad | G39: Tests unitarios de reglas críticas (continuo) | H39: Imprescindible | I39: Fundación | J39: 1 | K39: Áreas transversales | L39: QA-01-001 | M39: Backend | N39: 25 pruebas de dominio + 13 de integración (continuo)
A40: 35 | B40: =IF(C40="Completo","☑",IF(C40="En progreso","◐","☐")) | C40: En progreso | D40: ACC-M01 | E40: 01 · Identidad y Cuentas | F40: Mantenimiento | G40: Roles del sistema y matriz de permisos | H40: Imprescindible | I40: MVP | J40: 2 | K40: Red social | L40: OB-02, §8.1 | M40: Backend | N40: 10 roles sembrados (client por defecto). Falta asignar permisos por rol cuando existan los módulos
A41: 36 | B41: =IF(C41="Completo","☑",IF(C41="En progreso","◐","☐")) | C41: Completo | D41: ACC-M02 | E41: 01 · Identidad y Cuentas | F41: Mantenimiento | G41: Documentos legales versionados (términos, privacidad) | H41: Imprescindible | I41: MVP | J41: 2 | K41: Red social | L41: OB-01-001, OB-48-004 | M41: Backend | N41: Borrador→publicado inmutable, versión vigente por tipo/idioma
A42: 37 | B42: =IF(C42="Completo","☑",IF(C42="En progreso","◐","☐")) | C42: Completo | D42: ACC-M03 | E42: 01 · Identidad y Cuentas | F42: Mantenimiento | G42: Tipos de consentimiento (datos, marketing, ubicación) | H42: Imprescindible | I42: MVP | J42: 2 | K42: Red social | L42: OB-48-004 | M42: Backend | N42: Registro solo-anexar de consentimientos
A43: 38 | B43: =IF(C43="Completo","☑",IF(C43="En progreso","◐","☐")) | C43: Completo | D43: ACC-M04 | E43: 01 · Identidad y Cuentas | F43: Mantenimiento | G43: Política de contraseñas y bloqueo | H43: Imprescindible | I43: MVP | J43: 2 | K43: Red social | L43: OB-01-004 | M43: Backend | N43: 8+ caracteres, dígito y minúscula; bloqueo 15 min tras 5 intentos
A44: 39 | B44: =IF(C44="Completo","☑",IF(C44="En progreso","◐","☐")) | C44: Completo | D44: ACC-M05 | E44: 01 · Identidad y Cuentas | F44: Mantenimiento | G44: Plantillas de verificación email/SMS | H44: Imprescindible | I44: MVP | J44: 2 | K44: Red social | L44: OB-01-002/003 | M44: Backend | N44: Textos localizados es/en (texto plano). Mejorar a HTML con marca más adelante
A45: 40 | B45: =IF(C45="Completo","☑",IF(C45="En progreso","◐","☐")) | C45: Completo | D45: ACC-F01 | E45: 01 · Identidad y Cuentas | F45: Funcionalidad | G45: Registro por email/teléfono con consentimiento | H45: Imprescindible | I45: MVP | J45: 2 | K45: Red social | L45: OB-01-001 | M45: Backend | N45: /api/accounts/registration/register; errores genéricos
A46: 41 | B46: =IF(C46="Completo","☑",IF(C46="En progreso","◐","☐")) | C46: Completo | D46: ACC-F02 | E46: 01 · Identidad y Cuentas | F46: Funcionalidad | G46: Verificar correo | H46: Imprescindible | I46: MVP | J46: 2 | K46: Red social | L46: OB-01-002 | M46: Backend | N46: Código 6 dígitos con hash, 10 min, 5 intentos, reenvío 60 s, límite diario
A47: 42 | B47: =IF(C47="Completo","☑",IF(C47="En progreso","◐","☐")) | C47: En progreso | D47: ACC-F03 | E47: 01 · Identidad y Cuentas | F47: Funcionalidad | G47: Verificar teléfono (OTP) | H47: Imprescindible | I47: MVP | J47: 2 | K47: Red social | L47: OB-01-003 | M47: Backend | N47: Lógica lista; falta integrar un proveedor SMS real (hoy NullSmsSender)
A48: 43 | B48: =IF(C48="Completo","☑",IF(C48="En progreso","◐","☐")) | C48: En progreso | D48: ACC-F04 | E48: 01 · Identidad y Cuentas | F48: Funcionalidad | G48: Login Authorization Code + PKCE (reemplaza password grant) | H48: Imprescindible | I48: MVP | J48: 2 | K48: Red social | L48: OB-01-004 | M48: Backend | N48: PKCE obligatorio en el cliente. Password grant sigue activo (AllowPasswordFlow) hasta que la UI use PKCE
A49: 44 | B49: =IF(C49="Completo","☑",IF(C49="En progreso","◐","☐")) | C49: Completo | D49: ACC-F05 | E49: 01 · Identidad y Cuentas | F49: Funcionalidad | G49: Tokens de corta vida + rotación de refresh tokens | H49: Imprescindible | I49: MVP | J49: 2 | K49: Red social | L49: OB-47-003/004 | M49: Backend | N49: Access 15 min, refresh 14 días rotativo (probado)
... A53: 48 | B53: =IF(C53="Completo","☑",IF(C53="En progreso","◐","☐")) | C53: En progreso | D53: ACC-F09 | E53: 01 · Identidad y Cuentas | F53: Funcionalidad | G53: Alertas de seguridad de la cuenta | H53: Imprescindible | I53: MVP | J53: 2 | K53: Red social | L53: §13.1 | M53: Backend | N53: Handler implementado (cambio de contraseña/correo/teléfono, MFA, bloqueo); falta probar con SMTP real
A54: 49 | B54: =IF(C54="Completo","☑",IF(C54="En progreso","◐","☐")) | C54: En progreso | D54: ADM-M01 | E54: 26 · Administración y Auditoría | F54: Mantenimiento | G54: Usuarios internos y roles | H54: Imprescindible | I54: MVP | J54: 2 | K54: Gobierno | L54: OB-41
A55: 50 | B55: =IF(C55="Completo","☑",IF(C55="En progreso","◐","☐")) | C55: Pendiente | D55: LEG-M01 | E55: LEG · Cumplimiento Legal y Fiscal | F55: Mantenimiento | G55: Términos, privacidad, cancelación y acuerdo con profesionales (abogado) | H55: Imprescindible | I55: MVP | J55: 2 | K55: Áreas transversales | L55: OB-01-001, §21.2
A56: 51 | B56: =IF(C56="Completo","☑",IF(C56="En progreso","◐","☐")) | C56: Pendiente | D56: PRF-M01 | E56: 02 · Perfiles | F56: Mantenimiento | G56: Reglas de @usuario (formato, reservados, frecuencia de cambio) | H56: Imprescindible | I56: MVP | J56: 3 | K56: Red social | L56: —
A57: 52 | B57: =IF(C57="Completo","☑",IF(C57="En progreso","◐","☐")) | C57: Pendiente | D57: PRF-M02 | E57: 02 · Perfiles | F57: Mantenimiento | G57: Tipos de cuenta pública (cliente, profesional, negocio) | H57: Imprescindible | I57: MVP | J57: 3 | K57: Red social | L57: §8.1
A58: 53 | B58: =IF(C58="Completo","☑",IF(C58="En progreso","◐","☐")) | C58: Pendiente | D58: PRF-F01 | E58: 02 · Perfiles | F58: Funcionalidad | G58: Crear/editar perfil (foto, portada, bio, @usuario, enlaces) | H58: Imprescindible | I58: MVP | J58: 3 | K58: Red social | L58: OB-03-001, OB-07-001
A59: 54 | B59: =IF(C59="Completo","☑",IF(C59="En progreso","◐","☐")) | C59: Pendiente | D59: PRF-F02 | E59: 02 · Perfiles | F59: Funcionalidad | G59: Perfil público compartible sin datos privados | H59: Imprescindible | I59: MVP | J59: 3 | K59: Red social | L59: OB-07-001
...

Sheet Resumen
C2: Resumen de Avance
C3: Se recalcula automáticamente con la hoja Plan de Desarrollo
A6: Indicadores globales
A7: Total | B7: Completos | C7: En progreso | D7: Pendientes | E7: % Avance
A8: =COUNTA('Plan de Desarrollo'!$C$6:$C$425) | B8: =COUNTIF('Plan de Desarrollo'!$C$6:$C$425,"Completo") | C8: =COUNTIF('Plan de Desarrollo'!$C$6:$C$425,"En progreso") | D8: =COUNTIF('Plan de Desarrollo'!$C$6:$C$425,"Pendiente") | E8: =IFERROR(B8/A8,0)
A10: Avance por fase
A11: Fase | B11: Nivel | C11: Objetivo | D11: Sprints | E11: Total | F11: Completos | G11: %
A12: Fundación | B12: Imprescindible | C12: Base técnica segura y desplegable. | D12: S0–S1 | E12: =COUNTIF('Plan de Desarrollo'!$I$6:$I$425,"Fundación") | F12: =COUNTIFS('Plan de Desarrollo'!$I$6:$I$425,"Fundación",'Plan de Desarrollo'!$C$6:$C$425,"Completo") | G12: =IFERROR(F12/E12,0)
A13: MVP | B13: Imprescindible | C13: Red social + Reservar este look + pago con comisión. Lanzamiento al mercado. | D13: S2–S13 | E13: =COUNTIF('Plan de Desarrollo'!$I$6:$I$425,"MVP") | F13: =COUNTIFS('Plan de Desarrollo'!$I$6:$I$425,"MVP",'Plan de Desarrollo'!$C$6:$C$425,"Completo") | G13: =IFERROR(F13/E13,0)
A14: V1 | B14: Esencial | C14: Retención, confianza, video, wallet, promociones, apps móviles. | D14: S14–S20 | E14: =COUNTIF('Plan de Desarrollo'!$I$6:$I$425,"V1") | F14: =COUNTIFS('Plan de Desarrollo'!$I$6:$I$425,"V1",'Plan de Desarrollo'!$C$6:$C$425,"Completo") | G14: =IFERROR(F14/E14,0)
A15: V2 | B15: Expansión | C15: Owney Business OS: negocios, POS, inventario, fidelización. | D15: S21–S28 | E15: =COUNTIF('Plan de Desarrollo'!$I$6:$I$425,"V2") | F15: =COUNTIFS('Plan de Desarrollo'!$I$6:$I$425,"V2",'Plan de Desarrollo'!$C$6:$C$425,"Completo") | G15: =IFERROR(F15/E15,0)
A16: V3 | B16: Visión | C16: Eventos, Smart Pricing, IA y tienda de productos. | D16: S29–S34 | E16: =COUNTIF('Plan de Desarrollo'!$I$6:$I$425,"V3") | F16: =COUNTIFS('Plan de Desarrollo'!$I$6:$I$425,"V3",'Plan de Desarrollo'!$C$6:$C$425,"Completo") | G16: =IFERROR(F16/E16,0)
A18: Avance por módulo
A19: # | B19: Código | C19: Módulo | D19: Grupo | E19: Mantenimientos | F19: Funcionalidades | G19: Total | H19: Completos | I19: En progreso | J19: % | K19: Primer sprint
A20: 00 | B20: PLT | C20: Plataforma y Shared Kernel | D20: Base | E20: =COUNTIFS('Plan de Desarrollo'!$E$6:$E$425,"00 · Plataforma y Shared Kernel",'Plan de Desarrollo'!$F$6:$F$425,"Mantenimiento") | F20: =COUNTIFS('Plan de Desarrollo'!$E$6:$E$425,"00 · Plataforma y Shared Kernel",'Plan de Desarrollo'!$F$6:$F$425,"Funcionalidad") | G20: =COUNTIF('Plan de Desarrollo'!$E$6:$E$425,"00 · Plataforma y Shared Kernel") | H20: =COUNTIFS('Plan de Desarrollo'!$E$6:$E$425,"00 · Plataforma y Shared Kernel",'Plan de Desarrollo'!$C$6:$C$425,"Completo") | I20: =COUNTIFS('Plan de Desarrollo'!$E$6:$E$425,"00 · Plataforma y Shared Kernel",'Plan de Desarrollo'!$C$6:$C$425,"En progreso") | J20: =IFERROR(H20/G20,0) | K20: S0
A21: 01 | B21: ACC | C21: Identidad y Cuentas | D21: Red social | E21: =COUNTIFS('Plan de Desarrollo'!$E$6:$E$425,"01 · Identidad y Cuentas",'Plan de Desarrollo'!$F$6:$F$425,"Mantenimiento") | F21: =COUNTIFS('Plan de Desarrollo'!$E$6:$E$425,"01 · Identidad y Cuentas",'Plan de Desarrollo'!$F$6:$F$425,"Funcionalidad") | G21: =COUNTIF('Plan de Desarrollo'!$E$6:$E$425,"01 · Identidad y Cuentas") | H21: =COUNTIFS('Plan de Desarrollo'!$E$6:$E$425,"01 · Identidad y Cuentas",'Plan de Desarrollo'!$C$6:$C$425,"Completo") | I21: =COUNTIFS('Plan de Desarrollo'!$E$6:$E$425,"01 · Identidad y Cuentas",'Plan de Desarrollo'!$C$6:$C$425,"En progreso") | J21: =IFERROR(H21/G21,0) | K21: S2
A22: 02 | B22: PRF | C22: Perfiles | D22: Red social | E22: =COUNTIFS('Plan de Desarrollo'!$E$6:$E$425,"02 · Perfiles",'Plan de Desarrollo'!$F$6:$F$425,"Mantenimiento") | F22: =COUNTIFS('Plan de Desarrollo'!$E$6:$E$425,"02 · Perfiles",'Plan de Desarrollo'!$F$6:$F$425,"Funcionalidad") | G22: =COUNTIF('Plan de Desarrollo'!$E$6:$E$425,"02 · Perfiles") | H22: =COUNTIFS('Plan de Desarrollo'!$E$6:$E$425,"02 · Perfiles",'Plan de Desarrollo'!$C$6:$C$425,"Completo") | I22: =COUNTIFS('Plan de Desarrollo'!$E$6:$E$425,"02 · Perfiles",'Plan de Desarrollo'!$C$6:$C$425,"En progreso") | J22: =IFERROR(H22/G22,0) | K22: S3
A23: 03 | B23: GRF | C23: Grafo Social | D23: Red social | E23: =COUNTIFS('Plan de Desarrollo'!$E$6:$E$425,"03 · Grafo Social",'Plan de Desarrollo'!$F$6:$F$425,"Mantenimiento") | F23: =COUNTIFS('Plan de Desarrollo'!$E$6:$E$425,"03 · Grafo Social",'Plan de Desarrollo'!$F$6:$F$425,"Funcionalidad") | G23: =COUNTIF('Plan de Desarrollo'!$E$6:$E$425,"03 · Grafo Social") | H23: =COUNTIFS('Plan de Desarrollo'!$E$6:$E$425,"03 · Grafo Social",'Plan de Desarrollo'!$C$6:$C$425,"Completo") | I23: =COUNTIFS('Plan de Desarrollo'!$E$6:$E$425,"03 · Grafo Social",'Plan de Desarrollo'!$C$6:$C$425,"En progreso") | J23: =IFERROR(H23/G23,0) | K23: S3
A24: 04 | B24: CNT | C24: Contenido | D24: Red social | E24: =COUNTIFS('Plan de Desarrollo'!$E$6:$E$425,"04 · Contenido",'Plan de Desarrollo'!$F$6:$F$425,"Mantenimiento") | F24: =COUNTIFS('Plan de Desarrollo'!$E$6:$E$425,"04 · Contenido",'Plan de Desarrollo'!$F$6:$F$425,"Funcionalidad") | G24: =COUNTIF('Plan de Desarrollo'!$E$6:$E$425,"04 · Contenido") | H24: =COUNTIFS('Plan de Desarrollo'!$E$6:$E$425,"04 · Contenido",'Plan de Desarrollo'!$C$6:$C$425,"Completo") | I24: =COUNTIFS('Plan de Desarrollo'!$E$6:$E$425,"04 · Contenido",'Plan de Desarrollo'!$C$6:$C$425,"En progreso") | J24: =IFERROR(H24/G24,0) | K24: S4
A25: 05 | B25: FED | C25: Feed, Explorar y Búsqueda | D25: Red social | E25: =COUNTIFS('Plan de Desarrollo'!$E$6:$E$425,"05 · Feed, Explorar y Búsqueda",'Plan de Desarrollo'!$F$6:$F$425,"Mantenimiento") | F25: =COUNTIFS('Plan de Desarrollo'!$E$6:$E$425,"05 · Feed, Explorar y Búsqueda",'Plan de Desarrollo'!$F$6:$F$425,"Funcionalidad") | G25: =COUNTIF('Plan de Desarrollo'!$E$6:$E$425,"05 · Feed, Explorar y Búsqueda") | H25: =COUNTIFS('Plan de Desarrollo'!$E$6:$E$425,"05 · Feed, Explorar y Búsqueda",'Plan de Desarrollo'!$C$6:$C$425,"Completo") | I25: =COUNTIFS('Plan de Desarrollo'!$E$6:$E$425,"05 · Feed, Explorar y Búsqueda",'Plan de Desarrollo'!$C$6:$C$425,"En progreso") | J25: =IFERROR(H25/G25,0) | K25: S5
A26: 06 | B26: MSG | C26: Mensajería | D26: Red social | E26: =COUNTIFS('Plan de Desarrollo'!$E$6:$E$425,"06 · Mensajería",'Plan de Desarrollo'!$F$6:$F$425,"Mantenimiento") | F26: =COUNTIFS('Plan de Desarrollo'!$E$6:$E$425,"06 · Mensajería",'Plan de Desarrollo'!$F$6:$F$425,"Funcionalidad") | G26: =COUNTIF('Plan de Desarrollo'!$E$6:$E$425,"06 · Mensajería") | H26: =COUNTIFS('Plan de Desarrollo'!$E$6:$E$425,"06 · Mensajería",'Plan de Desarrollo'!$C$6:$C$425,"Completo") | I26: =COUNTIFS('Plan de Desarrollo'!$E$6:$E$425,"06 · Mensajería",'Plan de Desarrollo'!$C$6:$C$425,"En progreso") | J26: =IFERROR(H26/G26,0) | K26: S12
A27: 07 | B27: NTF | C27: Notificaciones | D27: Red social | E27: =COUNTIFS('Plan de Desarrollo'!$E$6:$E$425,"07 · Notificaciones",'Plan de Desarrollo'!$F$6:$F$425,"Mantenimiento") | F27: =COUNTIFS('Plan de Desarrollo'!$E$6:$E$425,"07 · Notificaciones",'Plan de Desarrollo'!$F$6:$F$425,"Funcionalidad") | G27: =COUNTIF('Plan de Desarrollo'!$E$6:$E$425,"07 · Notificaciones") | H27: =COUNTIFS('Plan de Desarrollo'!$E$6:$E$425,"07 · Notificaciones",'Plan de Desarrollo'!$C$6:$C$425,"Completo") | I27: =COUNTIFS('Plan de Desarrollo'!$E$6:$E$425,"07 · Notificaciones",'Plan de Desarrollo'!$C$6:$C$425,"En progreso") | J27: =IFERROR(H27/G27,0) | K27: S5
A28: 08 | B28: MED | C28: Media | D28: Soporte de la red | E28: =COUNTIFS('Plan de Desarrollo'!$E$6:$E$425,"08 · Media",'Plan de Desarrollo'!$F$6:$F$425,"Mantenimiento") | F28: =COUNTIFS('Plan de Desarrollo'!$E$6:$E$425,"08 · Media",'Plan de Desarrollo'!$F$6:$F$425,"Funcionalidad") | G28: =COUNTIF('Plan de Desarrollo'!$E$6:$E$425,"08 · Media") | H28: =COUNTIFS('Plan de Desarrollo'!$E$6:$E$425,"08 · Media",'Plan de Desarrollo'!$C$6:$C$425,"Completo") | I28: =COUNTIFS('Plan de Desarrollo'!$E$6:$E$425,"08 · Media",'Plan de Desarrollo'!$C$6:$C$425,"En progreso") | J28: =IFERROR(H28/G28,0) | K28: S3
A29: 09 | B29: TRS | C29: Confianza y Seguridad | D29: Soporte de la red | E29: =COUNTIFS('Plan de Desarrollo'!$E$6:$E$425,"09 · Confianza y Seguridad",'Plan de Desarrollo'!$F$6:$F$425,"Mantenimiento") | F29: =COUNTIFS('Plan de Desarrollo'!$E$6:$E$425,"09 · Confianza y Seguridad",'Plan de Desarrollo'!$F$6:$F$425,"Funcionalidad") | G29: =COUNTIF('Plan de Desarrollo'!$E$6:$E$425,"09 · Confianza y Seguridad") | H29: =COUNTIFS('Plan de Desarrollo'!$E$6:$E$425,"09 · Confianza y Seguridad",'Plan de Desarrollo'!$C$6:$C$425,"Completo") | I29: =COUNTIFS('Plan de Desarrollo'!$E$6:$E$425,"09 · Confianza y Seguridad",'Plan de Desarrollo'!$C$6:$C$425,"En progreso") | J29: =IFERROR(H29/G29,0) | K29: S5
A30: 10 | B30: VER | C30: Profesionales y Verificación | D30: Marketplace | E30: =COUNTIFS('Plan de Desarrollo'!$E$6:$E$425,"10 · Profesionales y Verificación",'Plan de Desarrollo'!$F$6:$F$425,"Mantenimiento") | F30: =COUNTIFS('Plan de Desarrollo'!$E$6:$E$425,"10 · Profesionales y Verificación",'Plan de Desarrollo'!$F$6:$F$425,"Funcionalidad") | G30: =COUNTIF('Plan de Desarrollo'!$E$6:$E$425,"10 · Profesionales y Verificación") | H30: =COUNTIFS('Plan de Desarrollo'!$E$6:$E$425,"10 · Profesionales y Verificación",'Plan de Desarrollo'!$C$6:$C$425,"Completo") | I30: =COUNTIFS('Plan de Desarrollo'!$E$6:$E$425,"10 · Profesionales y Verificación",'Plan de Desarrollo'!$C$6:$C$425,"En progreso") | J30: =IFERROR(H30/G30,0) | K30: S6
A31: 11 | B31: CAT | C31: Catálogo de Servicios | D31: Marketplace | E31: =COUNTIFS('Plan de Desarrollo'!$E$6:$E$425,"11 · Catálogo de Servicios",'Plan de Desarrollo'!$F$6:$F$425,"Mantenimiento") | F31: =COUNTIFS('Plan de Desarrollo'!$E$6:$E$425,"11 · Catálogo de Servicios",'Plan de Desarrollo'!$F$6:$F$425,"Funcionalidad") | G31: =COUNTIF('Plan de Desarrollo'!$E$6:$E$425,"11 · Catálogo de Servicios") | H31: =COUNTIFS('Plan de Desarrollo'!$E$6:$E$425,"11 · Catálogo de Servicios",'Plan de Desarrollo'!$C$6:$C$425,"Completo") | I31: =COUNTIFS('Plan de Desarrollo'!$E$6:$E$425,"11 · Catálogo de Servicios",'Plan de Desarrollo'!$C$6:$C$425,"En progreso") | J31: =IFERROR(H31/G31,0) | K31: S7
A32: 12 | B32: SCH | C32: Agenda y Disponibilidad | D32: Marketplace | E32: =COUNTIFS('Plan de Desarrollo'!$E$6:$E$425,"12 · Agenda y Disponibilidad",'Plan de Desarrollo'!$F$6:$F$425,"Mantenimiento") | F32: =COUNTIFS('Plan de Desarrollo'!$E$6:$E$425,"12 · Agenda y Disponibilidad",'Plan de Desarrollo'!$F$6:$F$425,"Funcionalidad") | G32: =COUNTIF('Plan de Desarrollo'!$E$6:$E$425,"12 · Agenda y Disponibilidad") | H32: =COUNTIFS('Plan de Desarrollo'!$E$6:$E$425,"12 · Agenda y Disponibilidad",'Plan de Desarrollo'!$C$6:$C$425,"Completo") | I32: =COUNTIFS('Plan de Desarrollo'!$E$6:$E$425,"12 · Agenda y Disponibilidad",'Plan de Desarrollo'!$C$6:$C$425,"En progreso") | J32: =IFERROR(H32/G32,0) | K32: S7
A33: 13 | B33: BKG | C33: Reservas | D33: Marketplace | E33: =COUNTIFS('Plan de Desarrollo'!$E$6:$E$425,"13 · Reservas",'Plan de Desarrollo'!$F$6:$F$425,"Mantenimiento") | F33: =COUNTIFS('Plan de Desarrollo'!$E$6:$E$425,"13 · Reservas",'Plan de Desarrollo'!$F$6:$F$425,"Funcionalidad") | G33: =COUNTIF('Plan de Desarrollo'!$E$6:$E$425,"13 · Reservas") | H33: =COUNTIFS('Plan de Desarrollo'!$E$6:$E$425,"13 · Reservas",'Plan de Desarrollo'!$C$6:$C$425,"Completo") | I33: =COUNTIFS('Plan de Desarrollo'!$E$6:$E$425,"13 · Reservas",'Plan de Desarrollo'!$C$6:$C$425,"En progreso") | J33: =IFERROR(H33/G33,0) | K33: S8
A34: 14 | B34: HOM | C34: Servicio a Domicilio | D34: Marketplace | E34: =COUNTIFS('Plan de Desarrollo'!$E$6:$E$425,"14 · Servicio a Domicilio",'Plan de Desarrollo'!$F$6:$F$425,"Mantenimiento") | F34: =COUNTIFS('Plan de Desarrollo'!$E$6:$E$425,"14 · Servicio a Domicilio",'Plan de Desarrollo'!$F$6:$F$425,"Funcionalidad") | G34: =COUNTIF('Plan de Desarrollo'!$E$6:$E$425,"14 · Servicio a Domicilio") | H34: =COUNTIFS('Plan de Desarrollo'!$E$6:$E$425,"14 · Servicio a Domicilio",'Plan de Desarrollo'!$C$6:$C$425,"Completo") | I34: =COUNTIFS('Plan de Desarrollo'!$E$6:$E$425,"14 · Servicio a Domicilio",'Plan de Desarrollo'!$C$6:$C$425,"En progreso") | J34: =IFERROR(H34/G34,0) | K34: S9
A35: 15 | B35: REP | C35: Reseñas y Reputación | D35: Marketplace | E35: =COUNTIFS('Plan de Desarrollo'!$E$6:$E$425,"15 · Reseñas y Reputación",'Plan de Desarrollo'!$F$6:$F$425,"Mantenimiento") | F35: =COUNTIFS('Plan de Desarrollo'!$E$6:$E$425,"15 · Reseñas y Reputación",'Plan de Desarrollo'!$F$6:$F$425,"Funcionalidad") | G35: =COUNTIF('Plan de Desarrollo'!$E$6:$E$425,"15 · Reseñas y Reputación") | H35: =COUNTIFS('Plan de Desarrollo'!$E$6:$E$425,"15 · Reseñas y Reputación",'Plan de Desarrollo'!$C$6:$C$425,"Completo") | I35: =COUNTIFS('Plan de Desarrollo'!$E$6:$E$425,"15 · Reseñas y Reputación",'Plan de Desarrollo'!$C$6:$C$425,"En progreso") | J35: =IFERROR(H35/G35,0) | K35: S11
A36: 16 | B36: MKT | C36: Promociones y Precios | D36: Marketplace | E36: =COUNTIFS('Plan de Desarrollo'!$E$6:$E$425,"16 · Promociones y Precios",'Plan de Desarrollo'!$F$6:$F$425,"Mantenimiento") | F36: =COUNTIFS('Plan de Desarrollo'!$E$6:$E$425,"16 · Promociones y Precios",'Plan de Desarrollo'!$F$6:$F$425,"Funcionalidad") | G36: =COUNTIF('Plan de Desarrollo'!$E$6:$E$425,"16 · Promociones y Precios") | H36: =COUNTIFS('Plan de Desarrollo'!$E$6:$E$425,"16 · Promociones y Precios",'Plan de Desarrollo'!$C$6:$C$425,"Completo") | I36: =COUNTIFS('Plan de Desarrollo'!$E$6:$E$425,"16 · Promociones y Precios",'Plan de Desarrollo'!$C$6:$C$425,"En progreso") | J36: =IFERROR(H36/G36,0) | K36: S18
A37: 17 | B37: PAY | C37: Pagos y Finanzas | D37: Dinero | E37: =COUNTIFS('Plan de Desarrollo'!$E$6:$E$425,"17 · Pagos y Finanzas",'Plan de Desarrollo'!$F$6:$F$425,"Mantenimiento") | F37: =COUNTIFS('Plan de Desarrollo'!$E$6:$E$425,"17 · Pagos y Finanzas",'Plan de Desarrollo'!$F$6:$F$425,"Funcionalidad") | G37: =COUNTIF('Plan de Desarrollo'!$E$6:$E$425,"17 · Pagos y Finanzas") | H37: =COUNTIFS('Plan de Desarrollo'!$E$6:$E$425,"17 · Pagos y Finanzas",'Plan de Desarrollo'!$C$6:$C$425,"Completo") | I37: =COUNTIFS('Plan de Desarrollo'!$E$6:$E$425,"17 · Pagos y Finanzas",'Plan de Desarrollo'!$C$6:$C$425,"En progreso") | J37: =IFERROR(H37/G37,0) | K37: S10
A38: 18 | B38: MON | C38: Monetización y Publicidad | D38: Dinero | E38: =COUNTIFS('Plan de Desarrollo'!$E$6:$E$425,"18 · Monetización y Publicidad",'Plan de Desarrollo'!$F$6:$F$425,"Mantenimiento") | F38: =COUNTIFS('Plan de Desarrollo'!$E$6:$E$425,"18 · Monetización y Publicidad",'Plan de Desarrollo'!$F$6:$F$425,"Funcionalidad") | G38: =COUNTIF('Plan de Desarrollo'!$E$6:$E$425,"18 · Monetización y Publicidad") | H38: =COUNTIFS('Plan de Desarrollo'!$E$6:$E$425,"18 · Monetización y Publicidad",'Plan de Desarrollo'!$C$6:$C$425,"Completo") | I38: =COUNTIFS('Plan de Desarrollo'!$E$6:$E$425,"18 · Monetización y Publicidad",'Plan de Desarrollo'!$C$6:$C$425,"En progreso") | J38: =IFERROR(H38/G38,0) | K38: S10
A39: 19 | B39: LOY | C39: Wallet y Fidelización | D39: Dinero | E39: =COUNTIFS('Plan de Desarrollo'!$E$6:$E$425,"19 · Wallet y Fidelización",'Plan de Desarrollo'!$F$6:$F$425,"Mantenimiento") | F39: =COUNTIFS('Plan de Desarrollo'!$E$6:$E$425,"19 · Wallet y Fidelización",'Plan de Desarrollo'!$F$6:$F$425,"Funcionalidad") | G39: =COUNTIF('Plan de Desarrollo'!$E$6:$E$425,"19 · Wallet y Fidelización") | H39: =COUNTIFS('Plan de Desarrollo'!$E$6:$E$425,"19 · Wallet y Fidelización",'Plan de Desarrollo'!$C$6:$C$425,"Completo") | I39: =COUNTIFS('Plan de Desarrollo'!$E$6:$E$425,"19 · Wallet y Fidelización",'Plan de Desarrollo'!$C$6:$C$425,"En progreso") | J39: =IFERROR(H39/G39,0) | K39: S18
A40: 20 | B40: BIZ | C40: Negocios y Equipo | D40: Negocios | E40: =COUNTIFS('Plan de Desarrollo'!$E$6:$E$425,"20 · Negocios y Equipo",'Plan de Desarrollo'!$F$6:$F$425,"Mantenimiento") | F40: =COUNTIFS('Plan de Desarrollo'!$E$6:$E$425,"20 · Negocios y Equipo",'Plan de Desarrollo'!$F$6:$F$425,"Funcionalidad") | G40: =COUNTIF('Plan de Desarrollo'!$E$6:$E$425,"20 · Negocios y Equipo") | H40: =COUNTIFS('Plan de Desarrollo'!$E$6:$E$425,"20 · Negocios y Equipo",'Plan de Desarrollo'!$C$6:$C$425,"Completo") | I40: =COUNTIFS('Plan de Desarrollo'!$E$6:$E$425,"20 · Negocios y Equipo",'Plan de Desarrollo'!$C$6:$C$425,"En progreso") | J40: =IFERROR(H40/G40,0) | K40: S21
A41: 21 | B41: BOP | C41: CRM, POS e Inventario | D41: Negocios | E41: =COUNTIFS('Plan de Desarrollo'!$E$6:$E$425,"21 · CRM, POS e Inventario",'Plan de Desarrollo'!$F$6:$F$425,"Mantenimiento") | F41: =COUNTIFS('Plan de Desarrollo'!$E$6:$E$425,"21 · CRM, POS e Inventario",'Plan de Desarrollo'!$F$6:$F$425,"Funcionalidad") | G41: =COUNTIF('Plan de Desarrollo'!$E$6:$E$425,"21 · CRM, POS e Inventario") | H41: =COUNTIFS('Plan de Desarrollo'!$E$6:$E$425,"21 · CRM, POS e Inventario",'Plan de Desarrollo'!$C$6:$C$425,"Completo") | I41: =COUNTIFS('Plan de Desarrollo'!$E$6:$E$425,"21 · CRM, POS e Inventario",'Plan de Desarrollo'!$C$6:$C$425,"En progreso") | J41: =IFERROR(H41/G41,0) | K41: S23
A42: 22 | B42: ANA | C42: Analítica | D42: Crecimiento | E42: =COUNTIFS('Plan de Desarrollo'!$E$6:$E$425,"22 · Analítica",'Plan de Desarrollo'!$F$6:$F$425,"Mantenimiento") | F42: =COUNTIFS('Plan de Desarrollo'!$E$6:$E$425,"22 · Analítica",'Plan de Desarrollo'!$F$6:$F$425,"Funcionalidad") | G42: =COUNTIF('Plan de Desarrollo'!$E$6:$E$425,"22 · Analítica") | H42: =COUNTIFS('Plan de Desarrollo'!$E$6:$E$425,"22 · Analítica",'Plan de Desarrollo'!$C$6:$C$425,"Completo") | I42: =COUNTIFS('Plan de Desarrollo'!$E$6:$E$425,"22 · Analítica",'Plan de Desarrollo'!$C$6:$C$425,"En progreso") | J42: =IFERROR(H42/G42,0) | K42: S12
A43: 23 | B43: EVT | C43: Eventos y Squad | D43: Crecimiento | E43: =COUNTIFS('Plan de Desarrollo'!$E$6:$E$425,"23 · Eventos y Squad",'Plan de Desarrollo'!$F$6:$F$425,"Mantenimiento") | F43: =COUNTIFS('Plan de Desarrollo'!$E$6:$E$425,"23 · Eventos y Squad",'Plan de Desarrollo'!$F$6:$F$425,"Funcionalidad") | G43: =COUNTIF('Plan de Desarrollo'!$E$6:$E$425,"23 · Eventos y Squad") | H43: =COUNTIFS('Plan de Desarrollo'!$E$6:$E$425,"23 · Eventos y Squad",'Plan de Desarrollo'!$C$6:$C$425,"Completo") | I43: =COUNTIFS('Plan de Desarrollo'!$E$6:$E$425,"23 · Eventos y Squad",'Plan de Desarrollo'!$C$6:$C$425,"En progreso") | J43: =IFERROR(H43/G43,0) | K43: S29
A44: 24 | B44: AI | C44: Inteligencia Artificial | D44: Crecimiento | E44: =COUNTIFS('Plan de Desarrollo'!$E$6:$E$425,"24 · Inteligencia Artificial",'Plan de Desarrollo'!$F$6:$F$425,"Mantenimiento") | F44: =COUNTIFS('Plan de Desarrollo'!$E$6:$E$425,"24 · Inteligencia Artificial",'Plan de Desarrollo'!$F$6:$F$425,"Funcionalidad") | G44: =COUNTIF('Plan de Desarrollo'!$E$6:$E$425,"24 · Inteligencia Artificial") | H44: =COUNTIFS('Plan de Desarrollo'!$E$6:$E$425,"24 · Inteligencia Artificial",'Plan de Desarrollo'!$C$6:$C$425,"Completo") | I44: =COUNTIFS('Plan de Desarrollo'!$E$6:$E$425,"24 · Inteligencia Artificial",'Plan de Desarrollo'!$C$6:$C$425,"En progreso") | J44: =IFERROR(H44/G44,0) | K44: S31
A45: 25 | B45: SHP | C45: Tienda de Productos | D45: Crecimiento | E45: =COUNTIFS('Plan de Desarrollo'!$E$6:$E$425,"25 · Tienda de Productos",'Plan de Desarrollo'!$F$6:$F$425,"Mantenimiento") | F45: =COUNTIFS('Plan de Desarrollo'!$E$6:$E$425,"25 · Tienda de Productos",'Plan de Desarrollo'!$F$6:$F$425,"Funcionalidad") | G45: =COUNTIF('Plan de Desarrollo'!$E$6:$E$425,"25 · Tienda de Productos") | H45: =COUNTIFS('Plan de Desarrollo'!$E$6:$E$425,"25 · Tienda de Productos",'Plan de Desarrollo'!$C$6:$C$425,"Completo") | I45: =COUNTIFS('Plan de Desarrollo'!$E$6:$E$425,"25 · Tienda de Productos",'Plan de Desarrollo'!$C$6:$C$425,"En progreso") | J45: =IFERROR(H45/G45,0) | K45: S33
...

Sheet Sprints
C2: Plan de Sprints
C3: Sprints de 2 semanas · el avance se calcula desde la hoja Plan de Desarrollo
A6: Sprint | B6: Fase | C6: Nivel | D6: Objetivo | E6: Elementos | F6: Completos | G6: En progreso | H6: %
A7: S0 | B7: Fundación | C7: Imprescindible | D7: Base segura y desplegable (secretos, limpieza, Railway, CI) | E7: =COUNTIF('Plan de Desarrollo'!$J$6:$J$425,0) | F7: =COUNTIFS('Plan de Desarrollo'!$J$6:$J$425,0,'Plan de Desarrollo'!$C$6:$C$425,"Completo") | G7: =COUNTIFS('Plan de Desarrollo'!$J$6:$J$425,0,'Plan de Desarrollo'!$C$6:$C$425,"En progreso") | H7: =IFERROR(F7/E7,0)
A8: S1 | B8: Fundación | C8: Imprescindible | D8: Plataforma modular (outbox, Redis, worker, observabilidad) — Fundación lista | E8: =COUNTIF('Plan de Desarrollo'!$J$6:$J$425,1) | F8: =COUNTIFS('Plan de Desarrollo'!$J$6:$J$425,1,'Plan de Desarrollo'!$C$6:$C$425,"Completo") | G8: =COUNTIFS('Plan de Desarrollo'!$J$6:$J$425,1,'Plan de Desarrollo'!$C$6:$C$425,"En progreso") | H8: =IFERROR(F8/E8,0)
A9: S2 | B9: MVP | C9: Imprescindible | D9: Identidad, cuentas y roles | E9: =COUNTIF('Plan de Desarrollo'!$J$6:$J$425,2) | F9: =COUNTIFS('Plan de Desarrollo'!$J$6:$J$425,2,'Plan de Desarrollo'!$C$6:$C$425,"Completo") | G9: =COUNTIFS('Plan de Desarrollo'!$J$6:$J$425,2,'Plan de Desarrollo'!$C$6:$C$425,"En progreso") | H9: =IFERROR(F9/E9,0)
A10: S3 | B10: MVP | C10: Imprescindible | D10: Perfiles, grafo social y media | E10: =COUNTIF('Plan de Desarrollo'!$J$6:$J$425,3) | F10: =COUNTIFS('Plan de Desarrollo'!$J$6:$J$425,3,'Plan de Desarrollo'!$C$6:$C$425,"Completo") | G10: =COUNTIFS('Plan de Desarrollo'!$J$6:$J$425,3,'Plan de Desarrollo'!$C$6:$C$425,"En progreso") | H10: =IFERROR(F10/E10,0)
A11: S4 | B11: MVP | C11: Imprescindible | D11: Contenido: publicaciones e interacciones | E11: =COUNTIF('Plan de Desarrollo'!$J$6:$J$425,4) | F11: =COUNTIFS('Plan de Desarrollo'!$J$6:$J$425,4,'Plan de Desarrollo'!$C$6:$C$425,"Completo") | G11: =COUNTIFS('Plan de Desarrollo'!$J$6:$J$425,4,'Plan de Desarrollo'!$C$6:$C$425,"En progreso") | H11: =IFERROR(F11/E11,0)
A12: S5 | B12: MVP | C12: Imprescindible | D12: Feed, Explorar, notificaciones sociales y moderación | E12: =COUNTIF('Plan de Desarrollo'!$J$6:$J$425,5) | F12: =COUNTIFS('Plan de Desarrollo'!$J$6:$J$425,5,'Plan de Desarrollo'!$C$6:$C$425,"Completo") | G12: =COUNTIFS('Plan de Desarrollo'!$J$6:$J$425,5,'Plan de Desarrollo'!$C$6:$C$425,"En progreso") | H12: =IFERROR(F12/E12,0)
A13: S6 | B13: MVP | C13: Imprescindible | D13: Profesionales y verificación (KYC) | E13: =COUNTIF('Plan de Desarrollo'!$J$6:$J$425,6) | F13: =COUNTIFS('Plan de Desarrollo'!$J$6:$J$425,6,'Plan de Desarrollo'!$C$6:$C$425,"Completo") | G13: =COUNTIFS('Plan de Desarrollo'!$J$6:$J$425,6,'Plan de Desarrollo'!$C$6:$C$425,"En progreso") | H13: =IFERROR(F13/E13,0)
A14: S7 | B14: MVP | C14: Imprescindible | D14: Catálogo de servicios y agenda | E14: =COUNTIF('Plan de Desarrollo'!$J$6:$J$425,7) | F14: =COUNTIFS('Plan de Desarrollo'!$J$6:$J$425,7,'Plan de Desarrollo'!$C$6:$C$425,"Completo") | G14: =COUNTIFS('Plan de Desarrollo'!$J$6:$J$425,7,'Plan de Desarrollo'!$C$6:$C$425,"En progreso") | H14: =IFERROR(F14/E14,0)
A15: S8 | B15: MVP | C15: Imprescindible | D15: Motor de disponibilidad y “Reservar este look” | E15: =COUNTIF('Plan de Desarrollo'!$J$6:$J$425,8) | F15: =COUNTIFS('Plan de Desarrollo'!$J$6:$J$425,8,'Plan de Desarrollo'!$C$6:$C$425,"Completo") | G15: =COUNTIFS('Plan de Desarrollo'!$J$6:$J$425,8,'Plan de Desarrollo'!$C$6:$C$425,"En progreso") | H15: =IFERROR(F15/E15,0)
A16: S9 | B16: MVP | C16: Imprescindible | D16: Domicilio y gestión de reservas | E16: =COUNTIF('Plan de Desarrollo'!$J$6:$J$425,9) | F16: =COUNTIFS('Plan de Desarrollo'!$J$6:$J$425,9,'Plan de Desarrollo'!$C$6:$C$425,"Completo") | G16: =COUNTIFS('Plan de Desarrollo'!$J$6:$J$425,9,'Plan de Desarrollo'!$C$6:$C$425,"En progreso") | H16: =IFERROR(F16/E16,0)
A17: S10 | B17: MVP | C17: Imprescindible | D17: Pagos reales y modelo de ingresos | E17: =COUNTIF('Plan de Desarrollo'!$J$6:$J$425,10) | F17: =COUNTIFS('Plan de Desarrollo'!$J$6:$J$425,10,'Plan de Desarrollo'!$C$6:$C$425,"Completo") | G17: =COUNTIFS('Plan de Desarrollo'!$J$6:$J$425,10,'Plan de Desarrollo'!$C$6:$C$425,"En progreso") | H17: =IFERROR(F17/E17,0)
A18: S11 | B18: MVP | C18: Imprescindible | D18: Ciclo del servicio, facturación, reseñas y avisos de reserva | E18: =COUNTIF('Plan de Desarrollo'!$J$6:$J$425,11) | F18: =COUNTIFS('Plan de Desarrollo'!$J$6:$J$425,11,'Plan de Desarrollo'!$C$6:$C$425,"Completo") | G18: =COUNTIFS('Plan de Desarrollo'!$J$6:$J$425,11,'Plan de Desarrollo'!$C$6:$C$425,"En progreso") | H18: =IFERROR(F18/E18,0)
A19: S12 | B19: MVP | C19: Imprescindible | D19: Mensajería en tiempo real, Discover de profesionales y métricas base | E19: =COUNTIF('Plan de Desarrollo'!$J$6:$J$425,12) | F19: =COUNTIFS('Plan de Desarrollo'!$J$6:$J$425,12,'Plan de Desarrollo'!$C$6:$C$425,"Completo") | G19: =COUNTIFS('Plan de Desarrollo'!$J$6:$J$425,12,'Plan de Desarrollo'!$C$6:$C$425,"En progreso") | H19: =IFERROR(F19/E19,0)
A20: S13 | B20: MVP | C20: Imprescindible | D20: Administración, cumplimiento y lanzamiento (go-live) — 🚩 LANZAMIENTO (MVP) | E20: =COUNTIF('Plan de Desarrollo'!$J$6:$J$425,13) | F20: =COUNTIFS('Plan de Desarrollo'!$J$6:$J$425,13,'Plan de Desarrollo'!$C$6:$C$425,"Completo") | G20: =COUNTIFS('Plan de Desarrollo'!$J$6:$J$425,13,'Plan de Desarrollo'!$C$6:$C$425,"En progreso") | H20: =IFERROR(F20/E20,0)
A21: S14 | B21: V1 | C21: Esencial | D21: Reels, stories, video, seguridad de cuenta y soporte | E21: =COUNTIF('Plan de Desarrollo'!$J$6:$J$425,14) | F21: =COUNTIFS('Plan de Desarrollo'!$J$6:$J$425,14,'Plan de Desarrollo'!$C$6:$C$425,"Completo") | G21: =COUNTIFS('Plan de Desarrollo'!$J$6:$J$425,14,'Plan de Desarrollo'!$C$6:$C$425,"En progreso") | H21: =IFERROR(F21/E21,0)
A22: S15 | B22: V1 | C22: Esencial | D22: Feed personalizado, tendencias y push | E22: =COUNTIF('Plan de Desarrollo'!$J$6:$J$425,15) | F22: =COUNTIFS('Plan de Desarrollo'!$J$6:$J$425,15,'Plan de Desarrollo'!$C$6:$C$425,"Completo") | G22: =COUNTIFS('Plan de Desarrollo'!$J$6:$J$425,15,'Plan de Desarrollo'!$C$6:$C$425,"En progreso") | H22: =IFERROR(F22/E22,0)
A23: S16 | B23: V1 | C23: Esencial | D23: Lista de espera, catálogo avanzado y tracking | E23: =COUNTIF('Plan de Desarrollo'!$J$6:$J$425,16) | F23: =COUNTIFS('Plan de Desarrollo'!$J$6:$J$425,16,'Plan de Desarrollo'!$C$6:$C$425,"Completo") | G23: =COUNTIFS('Plan de Desarrollo'!$J$6:$J$425,16,'Plan de Desarrollo'!$C$6:$C$425,"En progreso") | H23: =IFERROR(F23/E23,0)
A24: S17 | B24: V1 | C24: Esencial | D24: Owney Protect y pagos avanzados | E24: =COUNTIF('Plan de Desarrollo'!$J$6:$J$425,17) | F24: =COUNTIFS('Plan de Desarrollo'!$J$6:$J$425,17,'Plan de Desarrollo'!$C$6:$C$425,"Completo") | G24: =COUNTIFS('Plan de Desarrollo'!$J$6:$J$425,17,'Plan de Desarrollo'!$C$6:$C$425,"En progreso") | H24: =IFERROR(F24/E24,0)
A25: S18 | B25: V1 | C25: Esencial | D25: Payouts, promociones, wallet y suscripciones | E25: =COUNTIF('Plan de Desarrollo'!$J$6:$J$425,18) | F25: =COUNTIFS('Plan de Desarrollo'!$J$6:$J$425,18,'Plan de Desarrollo'!$C$6:$C$425,"Completo") | G25: =COUNTIFS('Plan de Desarrollo'!$J$6:$J$425,18,'Plan de Desarrollo'!$C$6:$C$425,"En progreso") | H25: =IFERROR(F25/E25,0)
A26: S19 | B26: V1 | C26: Esencial | D26: Privacidad, Beauty Passport, insignias y reputación avanzada | E26: =COUNTIF('Plan de Desarrollo'!$J$6:$J$425,19) | F26: =COUNTIFS('Plan de Desarrollo'!$J$6:$J$425,19,'Plan de Desarrollo'!$C$6:$C$425,"Completo") | G26: =COUNTIFS('Plan de Desarrollo'!$J$6:$J$425,19,'Plan de Desarrollo'!$C$6:$C$425,"En progreso") | H26: =IFERROR(F26/E26,0)
A27: S20 | B27: V1 | C27: Esencial | D27: Publicidad, métricas de creadores, rendimiento y apps móviles — 🚩 Hito V1 | E27: =COUNTIF('Plan de Desarrollo'!$J$6:$J$425,20) | F27: =COUNTIFS('Plan de Desarrollo'!$J$6:$J$425,20,'Plan de Desarrollo'!$C$6:$C$425,"Completo") | G27: =COUNTIFS('Plan de Desarrollo'!$J$6:$J$425,20,'Plan de Desarrollo'!$C$6:$C$425,"En progreso") | H27: =IFERROR(F27/E27,0)
A28: S21 | B28: V2 | C28: Expansión | D28: Negocios, sucursales y equipo | E28: =COUNTIF('Plan de Desarrollo'!$J$6:$J$425,21) | F28: =COUNTIFS('Plan de Desarrollo'!$J$6:$J$425,21,'Plan de Desarrollo'!$C$6:$C$425,"Completo") | G28: =COUNTIFS('Plan de Desarrollo'!$J$6:$J$425,21,'Plan de Desarrollo'!$C$6:$C$425,"En progreso") | H28: =IFERROR(F28/E28,0)
A29: S22 | B29: V2 | C29: Expansión | D29: Agenda de equipo | E29: =COUNTIF('Plan de Desarrollo'!$J$6:$J$425,22) | F29: =COUNTIFS('Plan de Desarrollo'!$J$6:$J$425,22,'Plan de Desarrollo'!$C$6:$C$425,"Completo") | G29: =COUNTIFS('Plan de Desarrollo'!$J$6:$J$425,22,'Plan de Desarrollo'!$C$6:$C$425,"En progreso") | H29: =IFERROR(F29/E29,0)
A30: S23 | B30: V2 | C30: Expansión | D30: CRM y puntos/referidos | E30: =COUNTIF('Plan de Desarrollo'!$J$6:$J$425,23) | F30: =COUNTIFS('Plan de Desarrollo'!$J$6:$J$425,23,'Plan de Desarrollo'!$C$6:$C$425,"Completo") | G30: =COUNTIFS('Plan de Desarrollo'!$J$6:$J$425,23,'Plan de Desarrollo'!$C$6:$C$425,"En progreso") | H30: =IFERROR(F30/E30,0)
A31: S24 | B31: V2 | C31: Expansión | D31: Membresías y paquetes | E31: =COUNTIF('Plan de Desarrollo'!$J$6:$J$425,24) | F31: =COUNTIFS('Plan de Desarrollo'!$J$6:$J$425,24,'Plan de Desarrollo'!$C$6:$C$425,"Completo") | G31: =COUNTIFS('Plan de Desarrollo'!$J$6:$J$425,24,'Plan de Desarrollo'!$C$6:$C$425,"En progreso") | H31: =IFERROR(F31/E31,0)
A32: S25 | B32: V2 | C32: Expansión | D32: POS (punto de venta) | E32: =COUNTIF('Plan de Desarrollo'!$J$6:$J$425,25) | F32: =COUNTIFS('Plan de Desarrollo'!$J$6:$J$425,25,'Plan de Desarrollo'!$C$6:$C$425,"Completo") | G32: =COUNTIFS('Plan de Desarrollo'!$J$6:$J$425,25,'Plan de Desarrollo'!$C$6:$C$425,"En progreso") | H32: =IFERROR(F32/E32,0)
A33: S26 | B33: V2 | C33: Expansión | D33: Inventario | E33: =COUNTIF('Plan de Desarrollo'!$J$6:$J$425,26) | F33: =COUNTIFS('Plan de Desarrollo'!$J$6:$J$425,26,'Plan de Desarrollo'!$C$6:$C$425,"Completo") | G33: =COUNTIFS('Plan de Desarrollo'!$J$6:$J$425,26,'Plan de Desarrollo'!$C$6:$C$425,"En progreso") | H33: =IFERROR(F33/E33,0)
A34: S27 | B34: V2 | C34: Expansión | D34: Comisiones de empleados y analítica de negocio | E34: =COUNTIF('Plan de Desarrollo'!$J$6:$J$425,27) | F34: =COUNTIFS('Plan de Desarrollo'!$J$6:$J$425,27,'Plan de Desarrollo'!$C$6:$C$425,"Completo") | G34: =COUNTIFS('Plan de Desarrollo'!$J$6:$J$425,27,'Plan de Desarrollo'!$C$6:$C$425,"En progreso") | H34: =IFERROR(F34/E34,0)
A35: S28 | B35: V2 | C35: Expansión | D35: Escala y escritorio (Windows/macOS) — 🚩 Hito V2 | E35: =COUNTIF('Plan de Desarrollo'!$J$6:$J$425,28) | F35: =COUNTIFS('Plan de Desarrollo'!$J$6:$J$425,28,'Plan de Desarrollo'!$C$6:$C$425,"Completo") | G35: =COUNTIFS('Plan de Desarrollo'!$J$6:$J$425,28,'Plan de Desarrollo'!$C$6:$C$425,"En progreso") | H35: =IFERROR(F35/E35,0)
A36: S29 | B36: V3 | C36: Visión | D36: Owney Events | E36: =COUNTIF('Plan de Desarrollo'!$J$6:$J$425,29) | F36: =COUNTIFS('Plan de Desarrollo'!$J$6:$J$425,29,'Plan de Desarrollo'!$C$6:$C$425,"Completo") | G36: =COUNTIFS('Plan de Desarrollo'!$J$6:$J$425,29,'Plan de Desarrollo'!$C$6:$C$425,"En progreso") | H36: =IFERROR(F36/E36,0)
A37: S30 | B37: V3 | C37: Visión | D37: Cronograma de eventos y Squad | E37: =COUNTIF('Plan de Desarrollo'!$J$6:$J$425,30) | F37: =COUNTIFS('Plan de Desarrollo'!$J$6:$J$425,30,'Plan de Desarrollo'!$C$6:$C$425,"Completo") | G37: =COUNTIFS('Plan de Desarrollo'!$J$6:$J$425,30,'Plan de Desarrollo'!$C$6:$C$425,"En progreso") | H37: =IFERROR(F37/E37,0)
A38: S31 | B38: V3 | C38: Visión | D38: Smart Pricing y Beauty Match | E38: =COUNTIF('Plan de Desarrollo'!$J$6:$J$425,31) | F38: =COUNTIFS('Plan de Desarrollo'!$J$6:$J$425,31,'Plan de Desarrollo'!$C$6:$C$425,"Completo") | G38: =COUNTIFS('Plan de Desarrollo'!$J$6:$J$425,31,'Plan de Desarrollo'!$C$6:$C$425,"En progreso") | H38: =IFERROR(F38/E38,0)
A39: S32 | B39: V3 | C39: Visión | D39: Asistente IA para negocios | E39: =COUNTIF('Plan de Desarrollo'!$J$6:$J$425,32) | F39: =COUNTIFS('Plan de Desarrollo'!$J$6:$J$425,32,'Plan de Desarrollo'!$C$6:$C$425,"Completo") | G39: =COUNTIFS('Plan de Desarrollo'!$J$6:$J$425,32,'Plan de Desarrollo'!$C$6:$C$425,"En progreso") | H39: =IFERROR(F39/E39,0)
A40: S33 | B40: V3 | C40: Visión | D40: Owney Shop: catálogo y órdenes | E40: =COUNTIF('Plan de Desarrollo'!$J$6:$J$425,33) | F40: =COUNTIFS('Plan de Desarrollo'!$J$6:$J$425,33,'Plan de Desarrollo'!$C$6:$C$425,"Completo") | G40: =COUNTIFS('Plan de Desarrollo'!$J$6:$J$425,33,'Plan de Desarrollo'!$C$6:$C$425,"En progreso") | H40: =IFERROR(F40/E40,0)
A41: S34 | B41: V3 | C41: Visión | D41: Owney Shop: pago y entrega — 🚩 Hito V3 | E41: =COUNTIF('Plan de Desarrollo'!$J$6:$J$425,34) | F41: =COUNTIFS('Plan de Desarrollo'!$J$6:$J$425,34,'Plan de Desarrollo'!$C$6:$C$425,"Completo") | G41: =COUNTIFS('Plan de Desarrollo'!$J$6:$J$425,34,'Plan de Desarrollo'!$C$6:$C$425,"En progreso") | H41: =IFERROR(F41/E41,0)

Sheet Módulos
C2: Catálogo de Módulos
C3: 27 módulos de código + 2 áreas transversales
A6: # | B6: Código | C6: Módulo | D6: Grupo | E6: Esquema BD | F6: Propósito | G6: Entidades principales
A7: 00 | B7: PLT | C7: Plataforma y Shared Kernel | D7: Base | E7: platform | F7: Base técnica común: valores compartidos, eventos con outbox, idempotencia, cache, worker, seguridad perimetral y observabilidad. Ningún módulo de negocio se construye sin ella. | G7: Money, Address, GeoPoint, DateTimeRange, IdempotencyRecord, OutboxMessage, InboxMessage, Province, Municipality, Sector, TaxRate
A8: 01 | B8: ACC | C8: Identidad y Cuentas | D8: Red social | E8: host + accounts | F8: Una identidad con varios roles (cliente, profesional, negocio). Registro, verificación, login seguro, cambio de modo y privacidad de la cuenta. | G8: IdentityUser (extendido), LegalDocumentVersion, UserConsent, VerificationChallenge, DataExportRequest, AccountDeletionRequest
A9: 02 | B9: PRF | C9: Perfiles | D9: Red social | E9: profiles | F9: Perfil público único con @usuario para clientes, profesionales y negocios. Es la “página” de cada persona en la red: bio, portafolio, servicios destacados, favoritos y Beauty Passport. | G9: Profile (@handle, tipo, visibilidad), ProfessionalShowcase, PortfolioItem, ClientAddress, Favorite, BeautyPreference, InspirationBoard
A10: 03 | B10: GRF | C10: Grafo Social | D10: Red social | E10: social_graph | F10: Relaciones entre perfiles: seguir, solicitudes, bloquear y silenciar. Base del feed y de la privacidad. | G10: Follow, FollowRequest, Block, Mute, FollowCounters (proyección)
A11: 04 | B11: CNT | C11: Contenido | D11: Red social | E11: content | F11: Publicaciones, interacciones y social commerce. Cada post puede etiquetar servicios y abrir “Reservar este look”. | G11: Post, PostMedia, Comment, Like, Save, Share, Hashtag, Mention, PostServiceTag, Reel, Story
A12: 05 | B12: FED | C12: Feed, Explorar y Búsqueda | D12: Red social | E12: discovery | F12: Cómo se descubre el contenido y a los profesionales: feed de seguidos, Explorar, búsqueda de perfiles/hashtags y Discover de profesionales con filtros, mapa y disponibilidad. | G12: FeedItem, ExploreTopic, ProviderSearchDocument (read model), SearchQueryLog, TrendingTopic
A13: 06 | B13: MSG | C13: Mensajería | D13: Red social | E13: messaging | F13: Mensajes directos entre usuarios y chat vinculado a cada reserva, en tiempo real. | G13: Conversation, ConversationParticipant, Message, MessageAttachment, MessageReceipt, MessageRequest
A14: 07 | B14: NTF | C14: Notificaciones | D14: Red social | E14: notifications | F14: Motor único que convierte eventos en avisos in-app, email, SMS y push, sin duplicados y con deep links. | G14: Notification, NotificationTemplate, NotificationPreference, DeviceToken, DeliveryLog
A15: 08 | B15: MED | C15: Media | D15: Soporte de la red | E15: media | F15: Subida, validación, procesamiento y entrega de fotos, videos y documentos. KYC en almacenamiento privado; contenido social por CDN. | G15: MediaAsset (propósito, visibilidad, estado), MediaVariant
A16: 09 | B16: TRS | C16: Confianza y Seguridad | D16: Soporte de la red | E16: trust | F16: Moderación de contenido (requisito de Apple/Google para apps con contenido de usuarios), disputas de reservas (Owney Protect) y soporte. | G16: ContentReport, ModerationCase, ModerationAction, AccountSanction, Dispute, DisputeEvidence, Appeal, SupportTicket, HelpArticle
A17: 10 | B17: VER | C17: Profesionales y Verificación | D17: Marketplace | E17: professionals | F17: Habilitar a un usuario como profesional: solicitud, documentos KYC, revisión administrativa e insignias de confianza. | G17: ProfessionalApplication, KycDocument (versionado), KycReviewDecision, Specialty, Certification, Badge
... A35: LEG | B35: LEG | C35: Cumplimiento Legal y Fiscal | D35: Áreas transversales | E35: — | F35: Lo necesario para operar legalmente en República Dominicana. Gran parte se hace con abogado y contador; aquí se controla qué debe implementar el producto y cuándo. Validar cada punto con asesoría local. | G35: —

Sheet Cómo usar
C2: Cómo usar este archivo
C3: Owney Beauty · Control de Desarrollo
B7: 1. Marcar avance | C7: En «Plan de Desarrollo», cambia la columna Estado. ☐ Pendiente · ◐ En progreso · ☑ Completo.
B8: 2. Orden | C8: La columna Orden es la prioridad: trabaja de arriba hacia abajo. El orden sigue los sprints.
B9: 3. Completo | C9: Solo marca Completo cuando cumple la Definition of Done (ver guía PDF): probado, seguro, auditado y desplegado en staging.
B10: 4. Filtros | C10: Usa los filtros del encabezado para ver un módulo, una fase, un sprint o solo lo pendiente.
B11: 5. Resumen | C11: Las hojas Resumen y Sprints se recalculan solas con fórmulas; no las edites a mano.
B12: Imprescindible | C12: Sin esto no se puede lanzar ni cobrar. (Fundación + MVP, S0–S13).
B13: Esencial | C13: Necesario para retener usuarios y crecer después del lanzamiento. (V1, S14–S20).
B14: Expansión | C14: Abre nuevas fuentes de ingreso (negocios y salones). (V2, S21–S28).
B15: Visión | C15: Diferenciación de largo plazo. (V3, S29–S34).
B16: Mantenimiento | C16: Catálogos, configuraciones, reglas y datos maestros que se administran (CRUD).
B17: Funcionalidad | C17: Casos de uso y flujos de negocio que operan sobre esos datos.
B18: Historias | C18: Referencia a las historias del Documento Maestro (OB-xx-xxx, TECH, QA…), donde están los criterios de aceptación.
